<?xml version="1.0" ?>

<robot name="RB1">

    <gazebo reference="base_link">
        <material>Gazebo/Black</material>
    </gazebo>
    <gazebo reference="link_Wheel1">
        <material>Gazebo/Grey</material>
    </gazebo>
    <gazebo reference="link_Wheel2">
        <material>Gazebo/Grey</material>
    </gazebo>
    <gazebo reference="link_front_caster_wheel">
        <material>Gazebo/Black</material>
    </gazebo>
    <gazebo reference="link_back_caster_wheel">
        <material>Gazebo/Black</material>
    </gazebo>

    <gazebo>
    <plugin filename="libgazebo_ros_diff_drive.so" name="differential_drive_controller">
        <alwaysOn>true</alwaysOn>
        <updateRate>20</updateRate>
        <leftJoint>Joint_Wheel1</leftJoint>
        <rightJoint>Joint_Wheel2</rightJoint>
        <wheelSeparation>0.4</wheelSeparation>
        <wheelDiameter>0.1</wheelDiameter>
        <torque>10</torque>
        <commandTopic>cmd_vel</commandTopic>
        <odometryTopic>odom</odometryTopic>
        <odometryFrame>odom</odometryFrame>
        <robotBaseFrame>link_chassis</robotBaseFrame>
    </plugin>
</gazebo>


<!-- Gazebo tags - Laser scan -->
<gazebo reference="joint_front_laser">
    <preserveFixedJoint>true</preserveFixedJoint>
</gazebo>
<gazebo reference="link_front_laser">
    <material>Gazebo/DarkGrey</material>
</gazebo>

<gazebo reference="link_front_laser">
    <sensor type="ray" name="head_hokuyo_sensor">
        <pose>0 0 0 0 0 0</pose>
        <visualize>true</visualize>
        <update_rate>20</update_rate>
        <ray>
            <scan>
                <horizontal>
                    <samples>720</samples>
                    <resolution>1</resolution>
                    <min_angle>-1.570796</min_angle>
                    <max_angle>1.570796</max_angle>
                </horizontal>
            </scan>
            <range>
                <min>0.20</min>
                <max>10.0</max>
                <resolution>0.01</resolution>
            </range>
            <noise>
                <type>gaussian</type>
                <mean>0.0</mean>
                <stddev>0.01</stddev>
            </noise>
        </ray>
        <plugin name="gazebo_ros_head_hokuyo_controller" filename="libgazebo_ros_laser.so">
            <topicName>/laser/scan</topicName>
            <frameName>sensor_laser</frameName>
        </plugin>
    </sensor>
</gazebo>    

    <!-- Link - base_link -->
    <link name="base_link">
        <inertial>
            <mass value="25" />
            <origin xyz="0 0 0" rpy="0 0 0" />
            <inertia ixx="0.57" ixy="0" ixz="0" iyy="0.57" iyz="0" izz="0.78" />
        </inertial>

        <collision>
            <geometry>
                <cylinder length="0.3" radius="0.25" />
            </geometry>
        </collision>

        <visual>
            <geometry>
                <cylinder length="0.3" radius="0.25" />
            </geometry>
        </visual>

    </link>

<!-- Joint - Wheel1 -->
<joint name="Joint_Wheel1" type="continuous">
    <origin rpy="0 0 0" xyz="0 -0.2 -0.15" />
    <child link="link_Wheel1" />
    <parent link="base_link" />
    <axis rpy="0 0 0" xyz="0 1 0" />
    <limit effort="10000" velocity="1000" />
    <joint_properties damping="1.0" friction="1.0" />
</joint>

<!-- Link - Wheel1 -->
<link name="link_Wheel1">
    <inertial>
        <mass value="1" />
        <origin xyz="0 0 0" rpy="0 0 0" />
        <inertia ixx="0.003" ixy="0" ixz="0" iyy="0.001" iyz="0" izz="0.003"/>
    </inertial>

    <collision>
        <origin rpy="1.5707 0 0" xyz="0 -0.008 0" />
        <geometry>
            <cylinder length="0.016" radius="0.05"/>
        </geometry>
    </collision>
    <visual>
        <origin rpy="1.5707 0 0" xyz="0 -0.008 0" />
        <geometry>
            <cylinder length="0.016" radius="0.05"/>
        </geometry>
    </visual>

</link>

<!-- Joint - Wheel2 -->
<joint name="Joint_Wheel2" type="continuous">
    <origin rpy="0 0 0" xyz="0 0.2 -0.15" />
    <child link="link_Wheel2" />
    <parent link="base_link" />
    <axis rpy="0 0 0" xyz="0 1 0" />
    <limit effort="10000" velocity="1000" />
    <joint_properties damping="1.0" friction="1.0" />
</joint>

<!-- Link - Wheel2 -->
<link name="link_Wheel2">
    <inertial>
        <mass value="1" />
        <origin xyz="0 0 0" rpy="0 0 0" />
        <inertia ixx="0.003" ixy="0" ixz="0" iyy="0.001" iyz="0" izz="0.003"/>
    </inertial>

    <collision>
        <origin rpy="1.5707 0 0" xyz="0 0.008 0" />
        <geometry>
            <cylinder length="0.016" radius="0.05"/>
        </geometry>
    </collision>
    <visual>
        <origin rpy="1.5707 0 0" xyz="0 0.008 0" />
        <geometry>
            <cylinder length="0.016" radius="0.05"/>
        </geometry>
    </visual>
</link>
    
<!-- Joint - front_caster wheel -->
<joint name="front__caster_wheel" type="fixed">
        <origin rpy="0 0 0" xyz="0.1 0 -0.15" />
        <child link="link_front_caster_wheel" />
        <parent link="base_link" />
        <joint_properties damping="1.0" friction="0" />
</joint>

<!-- Link - front_caster wheel -->
<link name="link_front_caster_wheel">
        <inertial>
            <mass value="1" />
            <origin xyz="0 0 0" rpy="0 0 0" />
            <inertia ixx="0.002526666666667" ixy="0" ixz="0" iyy="0.002526666666667" iyz="0" izz="0.005"/>
        </inertial>
    <!-- Caster wheel support -->
        <collision>
            <origin rpy="0 0 0" xyz="0 0 0.0125" />
            <geometry>
                <sphere radius="0.025" />
            </geometry>
        </collision>
        <visual>
            <origin rpy="0 0 0" xyz="0 0 0.0125" />
            <geometry>
                <sphere radius="0.025" />
            </geometry>
        </visual>
        <!-- Caster wheel -->
        <collision>
            <origin rpy="0 0 0" xyz="0 0 -0.0125" />
            <geometry>
                <sphere radius="0.010" />
            </geometry>
        </collision>
        <visual>
            <origin rpy="0 0 0" xyz="0 0 -0.0125" />
            <geometry>
                <sphere radius="0.010" />
            </geometry>
        </visual>
</link>

<!-- Joint - back_caster wheel -->
<joint name="back__caster_wheel" type="fixed">
        <origin rpy="0 0 0" xyz="-0.1 0 -0.15" />
        <child link="link_back_caster_wheel" />
        <parent link="base_link" />
        <joint_properties damping="1.0" friction="0" />
</joint>

<!-- Link - back_caster wheel -->
<link name="link_back_caster_wheel">
        <inertial>
            <mass value="1" />
            <origin xyz="0 0 0" rpy="0 0 0" />
            <inertia ixx="0.002526666666667" ixy="0" ixz="0" iyy="0.002526666666667" iyz="0" izz="0.005"/>
        </inertial>
    <!-- Caster wheel support -->
        <collision>
            <origin rpy="0 0 0" xyz="0 0 0.0125" />
            <geometry>
                <sphere radius="0.025" />
            </geometry>
        </collision>
        <visual>
            <origin rpy="0 0 0" xyz="0 0 0.0125" />
            <geometry>
                <sphere radius="0.025" />
            </geometry>
        </visual>
        <!-- Caster wheel -->
        <collision>
            <origin rpy="0 0 0" xyz="0 0 -0.0125" />
            <geometry>
                <sphere radius="0.010" />
            </geometry>
        </collision>
        <visual>
            <origin rpy="0 0 0" xyz="0 0 -0.0125" />
            <geometry>
                <sphere radius="0.010" />
            </geometry>
        </visual>
</link>

<!-- front laser -->
<joint name="joint_front_laser" type="fixed">
    <origin rpy="0 0 0" xyz="0.25 0 0.075" />
    <child link="link_front_laser" />
    <parent link="base_link" />
    <joint_properties damping="1.0" friction="1.0" />
</joint>

<link name="link_front_laser">
    <inertial>
        <origin xyz="0 0 0" rpy="3.1459 0 0" />
        <mass value="0.5" />
        <inertia ixx="0.00009" ixy="0" ixz="0" iyy="0.00009" iyz="0" izz="0.00011"/>
    </inertial>
    <visual>
        <origin xyz="0 0 0" rpy="0 0 0" />
        <geometry>
            <cylinder radius="0.015" length="0.020"/>
        </geometry>
        <material name="Blue">
            <color rgba="0 0 0.1 1" />
        </material>
    </visual>
    <collision>
        <origin xyz="0 0 0" rpy="0 0 0"/>
        <geometry>
            <cylinder radius="0.015" length="0.020"/>
        </geometry>
    </collision>
</link>
</robot>